<?xml version="1.0" encoding="UTF-8"?>
<!-- Generated by org.testng.reporters.JUnitReportReporter -->
<testsuite skipped="2" hostname="ADOE-20150303CS" name="com.yy.test.NewTest" tests="19" failures="1" timestamp="22 十一月 2018 06:03:17 GMT" time="2.769" errors="0">
  <testcase name="f" time="0.113" classname="com.yy.test.NewTest"/>
  <testcase name="f" time="1.205" classname="com.yy.test.NewTest"/>
  <testcase name="test1" time="0.008" classname="com.yy.test.NewTest"/>
  <testcase name="test3" time="0.000" classname="com.yy.test.NewTest">
    <skipped/>
  </testcase> <!-- test3 -->
  <testcase name="f" time="0.117" classname="com.yy.test.NewTest"/>
  <testcase name="f" time="0.104" classname="com.yy.test.NewTest"/>
  <testcase name="f" time="0.110" classname="com.yy.test.NewTest"/>
  <testcase name="f" time="0.129" classname="com.yy.test.NewTest"/>
  <testcase name="f" time="0.134" classname="com.yy.test.NewTest"/>
  <testcase name="f" time="0.121" classname="com.yy.test.NewTest"/>
  <testcase name="f" time="0.121" classname="com.yy.test.NewTest"/>
  <testcase name="f" time="0.133" classname="com.yy.test.NewTest"/>
  <testcase name="f" time="0.123" classname="com.yy.test.NewTest"/>
  <testcase name="f" time="0.121" classname="com.yy.test.NewTest"/>
  <testcase name="test3" time="0.004" classname="com.yy.test.NewTest">
    <failure type="java.lang.AssertionError" message="expected [1] but found [2]">
      <![CDATA[java.lang.AssertionError: expected [1] but found [2]
at org.testng.Assert.fail(Assert.java:96)
at org.testng.Assert.failNotEquals(Assert.java:776)
at org.testng.Assert.assertEqualsImpl(Assert.java:137)
at org.testng.Assert.assertEquals(Assert.java:118)
at org.testng.Assert.assertEquals(Assert.java:453)
at org.testng.Assert.assertEquals(Assert.java:463)
at com.yy.test.NewTest.test3(NewTest.java:36)
at sun.reflect.NativeMethodAccessorImpl.invoke0(Native Method)
at sun.reflect.NativeMethodAccessorImpl.invoke(NativeMethodAccessorImpl.java:62)
at sun.reflect.DelegatingMethodAccessorImpl.invoke(DelegatingMethodAccessorImpl.java:43)
at java.lang.reflect.Method.invoke(Method.java:498)
at org.testng.internal.MethodInvocationHelper.invokeMethod(MethodInvocationHelper.java:124)
at org.testng.internal.Invoker.invokeMethod(Invoker.java:583)
at org.testng.internal.Invoker.retryFailed(Invoker.java:839)
at org.testng.internal.Invoker.invokeTestMethods(Invoker.java:1010)
at org.testng.internal.TestMethodWorker.invokeTestMethods(TestMethodWorker.java:125)
at org.testng.internal.TestMethodWorker.run(TestMethodWorker.java:109)
at org.testng.TestRunner.privateRun(TestRunner.java:648)
at org.testng.TestRunner.run(TestRunner.java:505)
at org.testng.SuiteRunner.runTest(SuiteRunner.java:455)
at org.testng.SuiteRunner.runSequentially(SuiteRunner.java:450)
at org.testng.SuiteRunner.privateRun(SuiteRunner.java:415)
at org.testng.SuiteRunner.run(SuiteRunner.java:364)
at org.testng.SuiteRunnerWorker.runSuite(SuiteRunnerWorker.java:52)
at org.testng.SuiteRunnerWorker.run(SuiteRunnerWorker.java:84)
at org.testng.TestNG.runSuitesSequentially(TestNG.java:1208)
at org.testng.TestNG.runSuitesLocally(TestNG.java:1137)
at org.testng.TestNG.runSuites(TestNG.java:1049)
at org.testng.TestNG.run(TestNG.java:1017)
at org.testng.remote.AbstractRemoteTestNG.run(AbstractRemoteTestNG.java:132)
at org.testng.remote.RemoteTestNG.initAndRun(RemoteTestNG.java:230)
at org.testng.remote.RemoteTestNG.main(RemoteTestNG.java:76)
]]>
    </failure>
  </testcase> <!-- test3 -->
  <testcase name="test3" time="0.000" classname="com.yy.test.NewTest">
    <skipped/>
  </testcase> <!-- test3 -->
  <testcase name="f" time="0.113" classname="com.yy.test.NewTest"/>
  <testcase name="test2" time="0.004" classname="com.yy.test.NewTest"/>
  <testcase name="f" time="0.109" classname="com.yy.test.NewTest"/>
</testsuite> <!-- com.yy.test.NewTest -->
